Workbook
Name SegmentaçãodeDados_Oficina: #N/A
Name SegmentaçãodeDados_Status: #N/A

Sheet Peças
A1: DATA | B1: FILTRO DE COMBUSTIVEL | C1: FILTRO DE AR | D1: FILTRO DE OLEO | E1: OLEO MOTOR 5W30 | F1: PASTILHA DE FREIO D/ | G1: FILTRO DE COMBUSTIVEL MASTER 2023 | H1: PASTILHA DE FREIO TRASEIRA | I1: DISCO DE FREIO D/ | J1: DISCO DE FREIO T/ | K1: FLUIDO DE FREIO DT 4 | L1: KIT CORRERIA ALTERNADOR 2.3 | M1: KIT CORRERIA ALTERNADOR 2023 | N1: OLEO HIDRAULICO | O1: PINÇA TRASEIRA | P1: PINÇA DIANTEIRA | Q1: COPO FILTRO MASTER ANTIGA 2.3 | R1: LAMPADA H7 | S1: LAMPADAS 1 POLO | T1: LAMPADA 2 POLO | U1: LAMPADA PINGUINHO | V1: SEMI EIXO D 2 | W1: SEMI EIXO E | X1: HOMOCINETICA | Y1: PIVO D/ | Z1: PIVO E/ | AA1: BIELETA | AB1: PULIA DO VIRA | AC1: SENSOR MAF | AD1: TERMINAL D/ | AE1: TERMINAL E/ | AF1: KIT AMORTECEDR D/E | AG1: KIT AMORTECEDOR | AH1: BOMBA DO TANQUE | AI1: BOMBA DE ALTA RECONDICIONADA | AJ1: BOMBA DIREÇÃO | AK1: MANGUEIRA DE PRESSAO DA CIAXA | AL1: AGUA DESTILADA | AM1: ATUADOR PEDAL | AN1: CILINDRO MESTRE | AO1: ATUADOR CAMBIO | AP1: TAMPA RESERVATORIO | AQ1: CAIXA DE DIREÇÃO | AR1: TUBO TBI | AS1: MANGUEIRA INFERIOR DO RADIADOR | AT1: RECONDICIONAMENTO TURBINA | AU1: INTERCOOLER | AV1: RETROVISOR | AW1: RADIADOR | AX1: OLEO CAMBIO 75 W 80 | AY1: EMBREAGEM
A2: 45727 | B2: 25 | C2: 25 | D2: 25 | E2: 100 | F2: 20 | G2: 7 | H2: 20 | I2: 10 | J2: 10 | K2: 28 | L2: 4 | M2: 2 | N2: 15 | O2: 2 | P2: 0 | Q2: 2 | R2: 20 | S2: 20 | T2: 20 | U2: 20 | V2: 2 | W2: 2 | X2: 6 | Y2: 6 | Z2: 6 | AA2: 6 | AB2: 3 | AC2: 2 | AD2: 2 | AE2: 2 | AF2: 2 | AG2: 0 | AH2: 1 | AI2: 0 | AJ2: 5 | AK2: 4 | AL2: 6 | AM2: 5 | AN2: 0 | AO2: 2 | AP2: 3 | AQ2: 3 | AR2: 3 | AS2: 3 | AT2: 0 | AU2: 2 | AV2: 0 | AW2: 0 | AX2: 24 | AY2: 0
A3: 45727 | B3: 1 | C3: 1 | D3: 1 | E3: 8 | F3: 0 | G3: 0 | H3: 1 | I3: 0 | J3: 0 | K3: 1 | L3: 1 | M3: 0 | N3: 0 | O3: 1 | P3: 0 | Q3: 1 | R3: 0 | S3: 0 | T3: 0 | U3: 0 | V3: 0 | W3: 0 | X3: 0 | Y3: 0 | Z3: 0 | AA3: 0 | AB3: 0 | AC3: 0 | AD3: 0 | AE3: 0 | AF3: 0 | AG3: 0 | AH3: 0 | AI3: 0 | AJ3: 0 | AK3: 0 | AL3: 0 | AM3: 0 | AN3: 0 | AO3: 0 | AP3: 0 | AQ3: 0 | AR3: 0 | AS3: 0 | AT3: 0 | AU3: 0 | AV3: 0 | AW3: 0 | AX3: 0 | AY3: 0
A4: 45728 | B4: 0 | C4: 1 | D4: 1 | E4: 8 | F4: 0 | G4: 1 | H4: 0 | I4: 0 | J4: 0 | K4: 0 | L4: 0 | M4: 0 | N4: 0 | O4: 0 | P4: 0 | Q4: 0 | R4: 0 | S4: 0 | T4: 0 | U4: 0 | V4: 0 | W4: 0 | X4: 0 | Y4: 0 | Z4: 0 | AA4: 0 | AB4: 0 | AC4: 0 | AD4: 0 | AE4: 0 | AF4: 0 | AG4: 0 | AH4: 0 | AI4: 0 | AJ4: 0 | AK4: 0 | AL4: 0 | AM4: 0 | AN4: 0 | AO4: 0 | AP4: 0 | AQ4: 0 | AR4: 0 | AS4: 0 | AT4: 0 | AU4: 0 | AV4: 0 | AW4: 0 | AX4: 0 | AY4: 0
A5: 45729 | B5: 0 | C5: 0 | D5: 0 | E5: 0 | F5: 1 | G5: 0 | H5: 1 | I5: 0 | J5: 0 | K5: 0 | L5: 0 | M5: 0 | N5: 1 | O5: 0 | P5: 0 | Q5: 0 | R5: 0 | V5: 0 | W5: 0 | X5: 0 | Y5: 0 | Z5: 0 | AA5: 0 | AB5: 0 | AC5: 0 | AD5: 0 | AE5: 0 | AF5: 0 | AG5: 0 | AH5: 0 | AI5: 0 | AJ5: 2 | AK5: 0 | AL5: 2 | AM5: 0 | AN5: 0 | AO5: 0 | AP5: 0 | AQ5: 0 | AR5: 0 | AS5: 0 | AT5: 0 | AU5: 0 | AV5: 0 | AW5: 0 | AX5: 0 | AY5: 0
A6: 45730 | B6: 1 | C6: 0 | D6: 0 | E6: 4 | F6: 0 | G6: 0 | H6: 0 | I6: 0 | J6: 0 | K6: 0 | L6: 0 | M6: 0 | N6: 0 | O6: 0 | P6: 0 | Q6: 0 | R6: 0 | S6: 0 | T6: 0 | U6: 0 | V6: 0 | W6: 0 | X6: 0 | Y6: 0 | Z6: 0 | AA6: 0 | AB6: 0 | AC6: 1 | AE6: 0 | AF6: 0 | AG6: 0 | AH6: 0 | AI6: 0 | AJ6: 0 | AK6: 0 | AL6: 0 | AM6: 0 | AN6: 0 | AO6: 0 | AP6: 0 | AQ6: 0 | AR6: 0 | AS6: 0 | AT6: 0 | AU6: 0 | AV6: 0 | AW6: 0 | AX6: 0 | AY6: 0
A7: 45733 | B7: 0 | C7: 0 | D7: 0 | E7: 0 | F7: 0 | G7: 0 | H7: 0 | I7: 0 | J7: 0 | K7: 0 | L7: 0 | M7: 0 | N7: 0 | O7: 0 | P7: 0 | Q7: 0 | R7: 0 | S7: 0 | T7: 0 | U7: 0 | V7: 0 | W7: 0 | X7: 0 | Y7: 0 | Z7: 0 | AA7: 0 | AB7: 0 | AC7: 0 | AD7: 0 | AE7: 0 | AF7: 0 | AG7: 0 | AH7: 0 | AI7: 0 | AJ7: 0 | AK7: 0 | AL7: 0 | AM7: 0 | AN7: 0 | AO7: 0 | AP7: 1 | AQ7: 0 | AR7: 0 | AS7: 0 | AT7: 0 | AU7: 0 | AV7: 0 | AW7: 0 | AX7: 0 | AY7: 0
A8: 45733 | B8: 0 | C8: 0 | E8: 0 | F8: 0 | G8: 0 | H8: 1 | I8: 0 | J8: 1 | K8: 1 | L8: 0 | M8: 0 | N8: 2 | O8: 0 | P8: 0 | Q8: 0 | R8: 0 | S8: 0 | T8: 0 | U8: 0 | V8: 0 | W8: 0 | X8: 1 | Y8: 1 | Z8: 1 | AA8: 2 | AB8: 0 | AC8: 0 | AD8: 1 | AE8: 1 | AF8: 0 | AG8: 0 | AH8: 0 | AI8: 0 | AJ8: 0 | AK8: 0 | AL8: 0 | AM8: 0 | AN8: 0 | AO8: 0 | AP8: 0 | AQ8: 1 | AR8: 1 | AS8: 0 | AT8: 0 | AU8: 1 | AV8: 0 | AW8: 0 | AX8: 0 | AY8: 0
A9: 45733 | B9: 0 | C9: 0 | D9: 0 | E9: 0 | F9: 0 | G9: 0 | H9: 0 | I9: 0 | J9: 0 | K9: 0 | L9: 0 | M9: 0 | N9: 0 | O9: 0 | P9: 0 | Q9: 0 | R9: 0 | S9: 0 | T9: 0 | U9: 0 | V9: 0 | W9: 0 | X9: 0 | Y9: 0 | Z9: 0 | AA9: 0 | AB9: 0 | AC9: 0 | AD9: 0 | AE9: 0 | AF9: 0 | AG9: 0 | AH9: 0 | AI9: 0 | AJ9: 0 | AK9: 0 | AL9: 0 | AM9: 0 | AN9: 0 | AO9: 0 | AP9: 0 | AR9: 1 | AS9: 0 | AT9: 1 | AU9: 0 | AV9: 0 | AX9: 0 | AY9: 0
A10: 45735 | B10: 0 | C10: 0 | D10: 0 | E10: 0 | F10: 0 | G10: 0 | H10: 0 | I10: 0 | J10: 0 | K10: 0 | L10: 0 | M10: 0 | N10: 0 | O10: 0 | P10: 0 | Q10: 0 | R10: 0 | S10: 0 | T10: 0 | U10: 0 | V10: 0 | W10: 0 | X10: 0 | Y10: 0 | Z10: 0 | AA10: 0 | AB10: 0 | AC10: 0 | AD10: 0 | AE10: 0 | AF10: 0 | AG10: 0 | AH10: 0 | AI10: 0 | AJ10: 0 | AK10: 0 | AL10: 0 | AM10: 0 | AN10: 0 | AO10: 0 | AP10: 0 | AQ10: 0 | AR10: 1 | AS10: 0 | AT10: 0 | AU10: 0 | AV10: 0 | AW10: 0 | AX10: 0 | AY10: 0
A11: 45736 | B11: 1 | C11: 1 | D11: 1 | E11: 8 | F11: 0 | G11: 0 | H11: 1 | I11: 2 | J11: 2 | K11: 0 | L11: 0 | M11: 0 | N11: 2 | O11: 0 | P11: 0 | Q11: 1 | R11: 0 | S11: 0 | T11: 0 | U11: 0 | V11: 0 | W11: 0 | X11: 2 | Y11: 0 | Z11: 0 | AA11: 0 | AB11: 0 | AC11: 0 | AD11: 0 | AE11: 0 | AF11: 0 | AG11: 2 | AH11: 0 | AI11: 0 | AJ11: 0 | AK11: 0 | AL11: 0 | AM11: 0 | AN11: 0 | AO11: 0 | AP11: 0 | AQ11: 0 | AR11: 0 | AS11: 1 | AT11: 0 | AU11: 1 | AV11: 0 | AW11: 0 | AX11: 0 | AY11: 0
A12: 45736 | B12: 1 | C12: 1 | D12: 1 | E12: 8 | F12: 0 | G12: 1 | H12: 1 | I12: 0 | J12: 1 | K12: 0 | L12: 0 | M12: 0 | N12: 0 | O12: 0 | P12: 0 | Q12: 0 | R12: 0 | S12: 0 | T12: 0 | U12: 0 | V12: 1 | W12: 1 | X12: 0 | Y12: 0 | Z12: 0 | AA12: 0 | AB12: 0 | AC12: 0 | AD12: 0 | AE12: 0 | AF12: 0 | AG12: 0 | AH12: 0 | AI12: 0 | AJ12: 1 | AK12: 0 | AL12: 0 | AM12: 0 | AN12: 0 | AO12: 0 | AP12: 0 | AQ12: 0 | AR12: 0 | AS12: 0 | AT12: 0 | AU12: 0 | AV12: 0 | AW12: 0 | AX12: 0 | AY12: 0
A13: 45737 | B13: 1 | C13: 1 | D13: 1 | E13: 8 | F13: 1 | G13: 0 | H13: 1 | I13: 0 | J13: 0 | K13: 0 | L13: 0 | M13: 0 | N13: 0 | O13: 0 | P13: 0 | Q13: 0 | R13: 0 | S13: 0 | T13: 0 | U13: 0 | V13: 0 | W13: 0 | X13: 0 | Y13: 0 | Z13: 0+ | AA13: 0 | AB13: 0 | AC13: 0 | AD13: 0 | AE13: 0 | AF13: 0 | AG13: 0 | AH13: 1 | AI13: 0 | AJ13: 0 | AK13: 0 | AL13: 0 | AM13: 0 | AN13: 0 | AO13: 0 | AP13: 0 | AQ13: 0 | AR13: 0 | AS13: 0 | AT13: 0 | AU13: 0 | AV13: 0 | AW13: 0 | AX13: 0 | AY13: 0
A14: 45737 | B14: 1 | C14: 1 | D14: 1 | E14: 8 | F14: 1 | G14: 0 | H14: 1 | I14: 1 | J14: 1 | K14: 0 | L14: 0 | M14: 0 | N14: 0 | O14: 0 | P14: 0 | Q14: 0 | R14: 0 | S14: 0 | T14: 0 | U14: 0 | V14: 0 | W14: 0 | X14: 0 | Y14: 0 | Z14: 0 | AA14: 0 | AB14: 0 | AC14: 0 | AD14: 0 | AE14: 0 | AF14: 0 | AG14: 0 | AH14: 0 | AI14: 0 | AJ14: 0 | AK14: 0 | AL14: 0 | AM14: 0 | AN14: 0 | AO14: 0 | AP14: 0 | AQ14: 0 | AR14: 0 | AS14: 0 | AT14: 0 | AU14: 0 | AV14: 0 | AW14: 0 | AX14: 0 | AY14: 0
A15: 45740 | B15: 0 | C15: 0 | D15: 0 | E15: 0 | F15: 0 | G15: 0 | H15: 0 | I15: 0 | J15: 0 | K15: 0 | L15: 0 | M15: 0 | N15: 0 | O15: 0 | P15: 0 | Q15: 0 | R15: 0 | S15: 0 | T15: 0 | U15: 0 | V15: 0 | W15: 0 | X15: 1 | Y15: 0 | Z15: 0 | AA15: 0 | AB15: 0 | AC15: 0 | AD15: 0 | AE15: 0 | AF15: 0 | AG15: 0 | AH15: 0 | AI15: 0 | AJ15: 0 | AK15: 0 | AL15: 0 | AM15: 0 | AN15: 0 | AP15: 0 | AQ15: 0 | AR15: 0 | AS15: 0 | AT15: 0 | AV15: 0 | AW15: 0 | AX15: 0 | AY15: 0
A16: 45740 | B16: 0 | C16: 0 | D16: 0 | E16: 0 | F16: 0 | G16: 0 | H16: 0 | I16: 0 | J16: 0 | K16: 0 | L16: 1 | M16: 0 | N16: 0 | O16: 0 | P16: 0 | Q16: 0 | R16: 0 | S16: 0 | T16: 0 | U16: 0 | V16: 0 | W16: 0 | X16: 0 | Y16: 0 | Z16: 0 | AA16: 0 | AB16: 1 | AC16: 0 | AD16: 0 | AE16: 0 | AF16: 0 | AG16: 0 | AH16: 0 | AI16: 0 | AJ16: 0 | AK16: 0 | AL16: 0 | AM16: 0 | AN16: 0 | AO16: 0 | AP16: 0 | AQ16: 0 | AR16: 0 | AS16: 0 | AT16: 0 | AU16: 0 | AV16: 0 | AW16: 0 | AX16: 0 | AY16: 0
A17: 45740 | B17: 0 | C17: 0 | D17: 0 | E17: 0 | F17: 0 | G17: 0 | H17: 0 | I17: 0 | J17: 0 | K17: 0 | L17: 0 | M17: 0 | N17: 0 | O17: 0 | P17: 0 | Q17: 0 | R17: 0 | S17: 0 | T17: 0 | U17: 0 | V17: 0 | W17: 0 | X17: 0 | Y17: 0 | Z17: 0 | AA17: 0 | AB17: 0 | AC17: 0 | AD17: 0 | AE17: 0 | AF17: 0 | AG17: 0 | AH17: 0 | AI17: 1 | AJ17: 0 | AK17: 0 | AL17: 0 | AM17: 0 | AN17: 0 | AO17: 0 | AP17: 0 | AQ17: 0 | AR17: 0 | AS17: 0 | AT17: 0 | AU17: 0 | AV17: 0 | AW17: 0 | AX17: 0 | AY17: 0
A18: 45742 | B18: 0 | C18: 1 | D18: 1 | E18: 8 | F18: 0 | G18: 1 | H18: 1 | I18: 0 | J18: 0 | K18: 0 | L18: 0 | M18: 0 | N18: 0 | O18: 0 | P18: 0 | Q18: 0 | R18: 0 | S18: 0 | T18: 0 | U18: 0 | V18: 1 | W18: 0 | X18: 1 | Y18: 0 | Z18: 0 | AA18: 0 | AB18: 0 | AC18: 0 | AD18: 0 | AE18: 0 | AF18: 0 | AG18: 0 | AH18: 0 | AI18: 0 | AJ18: 0 | AK18: 0 | AL18: 0 | AM18: 0 | AN18: 0 | AO18: 0 | AP18: 0 | AQ18: 0 | AR18: 0 | AS18: 0 | AT18: 0 | AU18: 0 | AV18: 0 | AW18: 0 | AX18: 3 | AY18: 0
A19: 45743 | B19: 0 | C19: 0 | D19: 0 | E19: 0 | F19: 0 | G19: 0 | H19: 0 | I19: 0 | J19: 0 | K19: 0 | L19: 0 | M19: 0 | N19: 0 | O19: 1 | P19: 0 | Q19: 0 | R19: 0 | S19: 0 | T19: 0 | U19: 0 | V19: 0 | W19: 0 | X19: 0 | Y19: 0 | Z19: 0 | AA19: 0 | AB19: 0 | AC19: 0 | AD19: 0 | AE19: 0 | AF19: 0 | AG19: 0 | AH19: 0 | AI19: 0 | AJ19: 0 | AK19: 0 | AL19: 0 | AM19: 0 | AN19: 0 | AO19: 0 | AP19: 0 | AQ19: 0 | AR19: 0 | AS19: 0 | AT19: 0 | AU19: 0 | AV19: 0 | AW19: 0 | AX19: 0 | AY19: 0
A20: 45744 | B20: 1 | C20: 1 | D20: 1 | E20: 8 | F20: 0 | G20: 0 | H20: 0 | I20: 0 | J20: 0 | K20: 0 | L20: 0 | M20: 0 | N20: 0 | O20: 0 | P20: 0 | Q20: 0 | R20: 0 | S20: 0 | T20: 0 | U20: 0 | V20: 0 | W20: 0 | X20: 0 | Y20: 0 | Z20: 0 | AA20: 0 | AB20: 0 | AC20: 0 | AD20: 0 | AE20: 0 | AF20: 0 | AG20: 0 | AH20: 0 | AI20: 0 | AJ20: 0 | AK20: 0 | AL20: 0 | AM20: 0 | AN20: 0 | AO20: 0 | AP20: 0 | AQ20: 0 | AR20: 0 | AS20: 0 | AT20: 0 | AU20: 0 | AV20: 0 | AW20: 0 | AX20: 0 | AY20: 0
A21: 45744 | B21: 1 | C21: 1 | D21: 1 | E21: 8 | F21: 1 | G21: 0 | H21: 1 | I21: 0 | J21: 1 | K21: 0 | L21: 0 | M21: 0 | N21: 0 | O21: 0 | P21: 0 | Q21: 0 | R21: 0 | S21: 0 | T21: 0 | U21: 0 | V21: 0 | W21: 0 | X21: 0 | Y21: 0 | Z21: 0 | AA21: 0 | AB21: 0 | AC21: 0 | AD21: 0 | AE21: 0 | AF21: 0 | AG21: 0 | AH21: 0 | AI21: 0 | AJ21: 0 | AK21: 0 | AL21: 0 | AM21: 0 | AN21: 0 | AO21: 0 | AP21: 0 | AQ21: 0 | AR21: 0 | AS21: 0 | AT21: 0 | AU21: 0 | AV21: 0 | AW21: 0 | AX21: 0 | AY21: 0
A22: 45744 | B22: 0 | C22: 0 | D22: 0 | E22: 0 | F22: 0 | G22: 0 | H22: 0 | I22: 0 | J22: 0 | K22: 0 | L22: 0 | M22: 0 | N22: 0 | O22: 0 | P22: 0 | Q22: 0 | R22: 0 | S22: 0 | T22: 0 | U22: 0 | V22: 0 | W22: 0 | X22: 0 | Y22: 0 | Z22: 0 | AA22: 0 | AB22: 1 | AC22: 0 | AD22: 0 | AE22: 0 | AF22: 0 | AG22: 0 | AH22: 0 | AI22: 0 | AJ22: 0 | AK22: 0 | AL22: 0 | AM22: 0 | AN22: 0 | AO22: 0 | AP22: 0 | AQ22: 0 | AR22: 0 | AS22: 0 | AT22: 0 | AU22: 0 | AV22: 0 | AW22: 0 | AX22: 0 | AY22: 0
A23: 45748 | B23: 0 | C23: 1 | D23: 1 | E23: 8 | F23: 0 | G23: 1 | H23: 0 | I23: 0 | J23: 0 | K23: 0 | L23: 0 | M23: 0 | N23: 0 | O23: 0 | P23: 0 | Q23: 0 | R23: 0 | S23: 0 | T23: 0 | U23: 0 | V23: 0 | W23: 0 | X23: 0 | Y23: 1 | Z23: 0 | AA23: 0 | AB23: 0 | AC23: 0 | AD23: 0 | AE23: 0 | AF23: 0 | AG23: 0 | AI23: 0 | AJ23: 0 | AK23: 0 | AL23: 0 | AM23: 0 | AN23: 0 | AO23: 0 | AP23: 0 | AQ23: 0 | AR23: 0 | AS23: 0 | AT23: 0 | AU23: 0 | AV23: 0 | AW23: 0 | AX23: 0 | AY23: 0
A24: 45749 | B24: 0 | C24: 0 | D24: 0 | E24: 0 | F24: 0 | G24: 0 | H24: 0 | I24: 0 | J24: 0 | K24: 0 | L24: 1 | M24: 0 | N24: 0 | O24: 0 | P24: 0 | Q24: 0 | R24: 0 | S24: 0 | T24: 0 | U24: 0 | V24: 0 | W24: 0 | X24: 0 | Y24: 0 | Z24: 0 | AA24: 0 | AB24: 0 | AC24: 0 | AD24: 0 | AE24: 0 | AF24: 1 | AG24: 1 | AH24: 0 | AI24: 0 | AJ24: 0 | AK24: 0 | AL24: 0 | AM24: 0 | AN24: 0 | AO24: 0 | AP24: 0 | AQ24: 0 | AR24: 0 | AS24: 0 | AT24: 0 | AU24: 0 | AV24: 1 | AW24: 0 | AX24: 0 | AY24: 1
A25: 45749 | B25: 0 | C25: 0 | D25: 0 | E25: 0 | F25: 0 | G25: 0 | H25: 0 | I25: 0 | J25: 0 | K25: 0 | L25: 0 | M25: 0 | N25: 0 | O25: 0 | P25: 0 | Q25: 0 | R25: 0 | S25: 0 | T25: 0 | U25: 0 | V25: 0 | W25: 0 | X25: 0 | Y25: 0 | Z25: 0 | AA25: 0 | AB25: 0 | AC25: 0 | AD25: 0 | AE25: 0 | AF25: 0 | AG25: 0 | AH25: 0 | AI25: 0 | AJ25: 0 | AK25: 0 | AL25: 0 | AM25: 0 | AN25: 1 | AO25: 1 | AP25: 0 | AQ25: 0 | AR25: 0 | AS25: 0 | AT25: 0 | AU25: 0 | AV25: 0 | AW25: 0 | AX25: 0 | AY25: 0
A26: 45749 | B26: 0 | C26: 0 | D26: 0 | E26: 0 | F26: 1 | G26: 0 | H26: 1 | I26: 1 | J26: 1 | K26: 0 | L26: 0 | M26: 0 | N26: 0 | O26: 0 | P26: 0 | Q26: 0 | R26: 0 | S26: 0 | T26: 0 | U26: 0 | V26: 1 | W26: 0 | X26: 0 | Y26: 0 | Z26: 0 | AA26: 0 | AB26: 0 | AC26: 0 | AD26: 0 | AE26: 0 | AF26: 0 | AG26: 0 | AH26: 0 | AI26: 0 | AJ26: 0 | AK26: 0 | AL26: 0 | AM26: 0 | AN26: 0 | AO26: 0 | AP26: 0 | AQ26: 0 | AR26: 0 | AS26: 0 | AT26: 0 | AU26: 0 | AV26: 0 | AW26: 0 | AX26: 0 | AY26: 0
A27: 45751 | B27: 1 | C27: 0 | D27: 0 | E27: 0 | F27: 0 | G27: 0 | H27: 0 | I27: 0 | J27: 0 | K27: 0 | L27: 0 | M27: 0 | N27: 0 | O27: 0 | P27: 0 | Q27: 0 | R27: 0 | S27: 0 | T27: 0 | U27: 0 | V27: 0 | W27: 0 | X27: 0 | Y27: 0 | Z27: 0 | AA27: 0 | AB27: 0 | AC27: 0 | AD27: 0 | AE27: 0 | AF27: 0 | AG27: 0 | AH27: 0 | AI27: 0 | AJ27: 0 | AK27: 0 | AL27: 0 | AM27: 0 | AN27: 0 | AO27: 0 | AP27: 0 | AQ27: 0 | AR27: 0 | AS27: 0 | AT27: 0 | AU27: 0 | AV27: 0 | AW27: 0 | AX27: 0 | AY27: 0
A28: 45754 | B28: 0 | C28: 1 | D28: 1 | E28: 8 | F28: 0 | G28: 1 | H28: 0 | I28: 0 | J28: 0 | K28: 0 | L28: 0 | M28: 0 | N28: 0 | O28: 0 | P28: 0 | Q28: 0 | R28: 0 | S28: 0 | T28: 0 | U28: 0 | V28: 0 | W28: 0 | X28: 0 | Y28: 0 | Z28: 0 | AA28: 0 | AB28: 0 | AC28: 0 | AD28: 0 | AE28: 0 | AF28: 0 | AG28: 0 | AH28: 0 | AI28: 0 | AJ28: 0 | AK28: 0 | AL28: 0 | AM28: 0 | AN28: 0 | AO28: 0 | AP28: 0 | AQ28: 0 | AR28: 0 | AS28: 0 | AT28: 0 | AU28: 0 | AV28: 0 | AW28: 0 | AX28: 0 | AY28: 0
A29: 45754 | B29: 0 | C29: 0 | D29: 0 | E29: 0 | F29: 1 | G29: 0 | H29: 1 | I29: 1 | J29: 1 | K29: 0 | L29: 0 | M29: 0 | N29: 0 | O29: 0 | P29: 0 | Q29: 0 | R29: 0 | S29: 0 | T29: 0 | U29: 0 | V29: 0 | W29: 0 | X29: 0 | Y29: 0 | Z29: 0 | AA29: 0 | AB29: 0 | AC29: 0 | AD29: 0 | AE29: 0 | AF29: 0 | AG29: 0 | AH29: 0 | AI29: 0 | AJ29: 1 | AK29: 1 | AL29: 0 | AM29: 0 | AN29: 0 | AO29: 0 | AP29: 0 | AQ29: 0 | AR29: 0 | AS29: 0 | AT29: 1 | AU29: 0 | AV29: 0 | AW29: 0 | AX29: 0 | AY29: 0
A30: 45761 | B30: 1 | C30: 1 | D30: 1 | E30: 8 | F30: 0 | G30: 0 | H30: 0 | I30: 0 | J30: 0 | K30: 0 | L30: 0 | M30: 0 | N30: 0 | O30: 0 | P30: 0 | Q30: 0 | R30: 0 | S30: 0 | T30: 0 | U30: 0 | V30: 0 | W30: 0 | X30: 0 | Y30: 0 | Z30: 0 | AA30: 0 | AB30: 0 | AC30: 0 | AD30: 0 | AE30: 0 | AF30: 0 | AG30: 0 | AH30: 0 | AI30: 0 | AJ30: 0 | AK30: 0 | AL30: 0 | AM30: 0 | AN30: 0 | AO30: 0 | AP30: 0 | AQ30: 0 | AR30: 0 | AS30: 0 | AT30: 0 | AU30: 0 | AV30: 0 | AW30: 0 | AX30: 0 | AY30: 0
A31: 45761 | B31: 1 | C31: 1 | D31: 1 | E31: 8 | F31: 0 | G31: 0 | H31: 0 | I31: 0 | J31: 0 | K31: 0 | L31: 0 | M31: 0 | N31: 0 | O31: 0 | P31: 0 | Q31: 0 | R31: 0 | S31: 0 | T31: 0 | U31: 0 | V31: 0 | W31: 0 | X31: 0 | Y31: 0 | Z31: 0 | AA31: 0 | AB31: 0 | AC31: 0 | AD31: 0 | AE31: 0 | AF31: 0 | AG31: 0 | AH31: 0 | AI31: 0 | AJ31: 0 | AK31: 0 | AL31: 0 | AM31: 0 | AN31: 0 | AO31: 0 | AP31: 0 | AQ31: 0 | AR31: 0 | AS31: 0 | AT31: 0 | AU31: 0 | AV31: 0 | AW31: 0 | AX31: 0 | AY31: 0
A32: 45761 | B32: 0 | C32: 0 | D32: 0 | E32: 0 | F32: 0 | G32: 1 | H32: 0 | I32: 0 | J32: 0 | K32: 0 | L32: 0 | M32: 0 | N32: 0 | O32: 0 | P32: 0 | Q32: 0 | R32: 0 | T32: 0 | U32: 0 | V32: 0 | W32: 0 | X32: 0 | Y32: 0 | Z32: 0 | AA32: 0 | AB32: 0 | AC32: 0 | AD32: 0 | AE32: 0 | AF32: 0 | AG32: 0 | AH32: 0 | AI32: 0 | AJ32: 0 | AK32: 0 | AL32: 0 | AM32: 0 | AN32: 0 | AO32: 0 | AP32: 0 | AQ32: 0 | AR32: 0 | AS32: 0 | AT32: 0 | AU32: 0 | AV32: 0 | AW32: 0 | AX32: 0 | AY32: 0
A33: 45761 | B33: 1 | C33: 1 | D33: 1 | E33: 8 | F33: 0 | G33: 0 | H33: 0 | I33: 0 | J33: 0 | K33: 0 | L33: 0 | M33: 0 | N33: 0 | O33: 0 | P33: 0 | Q33: 0 | R33: 0 | S33: 0 | T33: 0 | U33: 0 | V33: 0 | W33: 0 | X33: 0 | Y33: 0 | Z33: 0 | AA33: 0 | AB33: 0 | AC33: 0 | AD33: 0 | AE33: 0 | AF33: 0 | AG33: 0 | AH33: 0 | AI33: 0 | AJ33: 0 | AK33: 0 | AL33: 0 | AM33: 0 | AN33: 0 | AO33: 0 | AP33: 0 | AQ33: 0 | AR33: 0 | AS33: 0 | AT33: 0 | AU33: 0 | AV33: 0 | AW33: 0 | AX33: 0 | AY33: 0
A34: 45761 | B34: 0 | C34: 0 | D34: 0 | E34: 0 | F34: 0 | G34: 0 | H34: 0 | I34: 0 | J34: 0 | K34: 0 | L34: 0 | N34: 0 | O34: 0 | P34: 0 | Q34: 0 | R34: 0 | S34: 0 | T34: 0 | V34: 0 | W34: 0 | X34: 0 | Y34: 0 | Z34: 0 | AA34: 0 | AB34: 0 | AC34: 0 | AD34: 0 | AE34: 0 | AF34: 0 | AG34: 0 | AH34: 0 | AI34: 0 | AJ34: 0 | AK34: 0 | AL34: 0 | AM34: 0 | AN34: 0 | AO34: 0 | AP34: 0 | AQ34: 0 | AR34: 0 | AS34: 0 | AT34: 1 | AU34: 0 | AV34: 0 | AW34: 0 | AX34: 0 | AY34: 0
A35: 45761 | B35: 1 | C35: 1 | D35: 0 | E35: 0 | F35: 0 | G35: 0 | H35: 0 | I35: 0 | J35: 0 | K35: 0 | L35: 0 | M35: 0 | N35: 0 | O35: 0 | P35: 0 | Q35: 0 | R35: 0 | S35: 0 | T35: 0 | U35: 0 | V35: 0 | W35: 0 | X35: 0 | Y35: 0 | Z35: 0 | AA35: 0 | AB35: 0 | AC35: 0 | AD35: 0 | AE35: 0 | AF35: 0 | AG35: 0 | AH35: 0 | AI35: 0 | AJ35: 0 | AK35: 0 | AL35: 0 | AM35: 0 | AN35: 0 | AO35: 0 | AP35: 0 | AQ35: 0 | AR35: 0 | AS35: 1 | AT35: 0 | AU35: 0 | AV35: 0 | AW35: 0 | AX35: 0 | AY35: 0
A36: 45762 | B36: 0 | C36: 1 | D36: 1 | E36: 8 | F36: 1 | G36: 1 | H36: 1 | I36: 1 | J36: 0 | K36: 0 | L36: 0 | M36: 0 | N36: 0 | O36: 0 | P36: 0 | Q36: 0 | R36: 0 | S36: 0 | T36: 0 | U36: 0 | V36: 0 | W36: 0 | X36: 0 | Y36: 0 | Z36: 0 | AA36: 0 | AB36: 0 | AC36: 0 | AD36: 0 | AE36: 0 | AF36: 0 | AG36: 0 | AH36: 0 | AI36: 0 | AJ36: 0 | AK36: 0 | AL36: 0 | AM36: 0 | AN36: 0 | AO36: 0 | AP36: 0 | AQ36: 0 | AR36: 0 | AS36: 0 | AT36: 0 | AU36: 0 | AV36: 0 | AW36: 0 | AX36: 0 | AY36: 0

Sheet Dados
A1: Coluna1
C3: oficina em debito | D3: Atendimento | E3: Placa | F3: Modelo | G3: km | H3: Relato | I3: Data Agenda | J3: Focal | K3: Reparo | L3: Tipo de Manutenção | M3: Aprovação | N3: Valor do Orçamento | O3: Valor Negociado | P3: Centro de Custo | Q3: Operação | R3: Status | S3: Previsão | T3: Liberado | U3: D+Manut | V3: Status2 | W3: Oficina | X3: Lider Base | Y3: Mês | Z3: Base
E4: SGK7D70 | F4: =IFERROR(VLOOKUP(Tabela1[[#This Row],[Placa]],'Base Cadastro '!A:B,2,FALSE),"Correção de cadastro") -> TRANSIT FURGÃO | H4: Funilaria dianteira total | I4: 45708 | J4: Vinicius | K4: Sinistro | L4: Corretiva | M4: Aprovado | N4: 22000 | O4: 22000 | P4: =VLOOKUP(Tabela1[[#This Row],[Placa]],'Base Cadastro '!A:M,13,FALSE) -> SSP8 | Q4: MERCADO LIVRE | R4: Sinistro | S4: 45974 | U4: =IFERROR(DATEDIF(Tabela1[[#This Row],[Data Agenda]],Tabela1[[#This Row],[Liberado]],"D"),DATEDIF(Tabela1[[#This Row],[Data Agenda]],TODAY(),"D")) -> 270 | V4: =IF(Tabela1[[#This Row],[D+Manut]]<=2,"Dentro do Prazo","Fora do Prazo") -> Fora do Prazo | W4: GR Car | X4: Gabriela | Y4: Fev | Z4: =VLOOKUP(Tabela1[[#This Row],[Placa]],DadosViagem5[[Placa]:[Base]],11,FALSE) -> SC (SAO JOSE DOS CAMPOS) SSP8
E5: SDT9G04 | F5: =IFERROR(VLOOKUP(Tabela1[[#This Row],[Placa]],'Base Cadastro '!A:B,2,FALSE),"Correção de cadastro") -> E-Jumpy Furgão 2P | G5: 34254 | H5: Funilaria lateral esquerda traseira. | I5: 45736 | J5: Vinicius | K5: Sinistro | L5: Corretiva | M5: Aprovado | N5: 19364.98 | O5: 19364.98 | P5: =VLOOKUP(Tabela1[[#This Row],[Placa]],'Base Cadastro '!A:M,13,FALSE) -> SRS1 | Q5: MERCADO LIVRE | R5: Sinistro | S5: 45974 | U5: 197 | V5: =IF(Tabela1[[#This Row],[D+Manut]]<=2,"Dentro do Prazo","Fora do Prazo") -> Fora do Prazo | W5: Safety Car | X5: ALESSANDRA | Y5: Set | Z5: =VLOOKUP(Tabela1[[#This Row],[Placa]],DadosViagem5[[Placa]:[Base]],11,FALSE) -> SC (PORTO ALEGRE) SRS1
A6: 0 | E6: RTM6B63 | F6: =IFERROR(VLOOKUP(Tabela1[[#This Row],[Placa]],'Base Cadastro '!A:B,2,FALSE),"Correção de cadastro") -> Master Furgão 8m³ | G6: N/E | H6: Veículo sofreu uma colisão no baú | I6: 45848 | J6: Vinicius | K6: Sinistro | L6: Corretiva | M6: Aprovado | P6: =VLOOKUP(Tabela1[[#This Row],[Placa]],'Base Cadastro '!A:M,13,FALSE) -> SRS1 | Q6: MERCADO LIVRE | R6: Sinistro | S6: Aguardando aprovação | U6: =IFERROR(DATEDIF(Tabela1[[#This Row],[Data Agenda]],Tabela1[[#This Row],[Liberado]],"D"),DATEDIF(Tabela1[[#This Row],[Data Agenda]],TODAY(),"D")) -> 130 | V6: =IF(Tabela1[[#This Row],[D+Manut]]<=2,"Dentro do Prazo","Fora do Prazo") -> Fora do Prazo | W6: Safety Car | Y6: Set | Z6: =VLOOKUP(Tabela1[[#This Row],[Placa]],DadosViagem5[[Placa]:[Base]],11,FALSE) -> SC (PORTO ALEGRE) SRS1
E7: FMO8E22 | F7: =IFERROR(VLOOKUP(Tabela1[[#This Row],[Placa]],'Base Cadastro '!A:B,2,FALSE),"Correção de cadastro") -> Partner Rapid Business Pack 1.4 2P | H7: Colisão não informada da base | J7: Vinicius | K7: Sinistro | L7: Corretiva | P7: =VLOOKUP(Tabela1[[#This Row],[Placa]],'Base Cadastro '!A:M,13,FALSE) -> SGO1 | Q7: MERCADO LIVRE | R7: Sinistro | S7: 45980 | U7: =IFERROR(DATEDIF(Tabela1[[#This Row],[Data Agenda]],Tabela1[[#This Row],[Liberado]],"D"),DATEDIF(Tabela1[[#This Row],[Data Agenda]],TODAY(),"D")) -> 0 | V7: =IF(Tabela1[[#This Row],[D+Manut]]<=2,"Dentro do Prazo","Fora do Prazo") -> Dentro do Prazo | W7: Auto reformadora Santos | Y7: Nov | Z7: =VLOOKUP(Tabela1[[#This Row],[Placa]],DadosViagem5[[Placa]:[Base]],11,FALSE) -> #N/A
E8: RUX2J10 | F8: =IFERROR(VLOOKUP(Tabela1[[#This Row],[Placa]],'Base Cadastro '!A:B,2,FALSE),"Correção de cadastro") -> Partner Rapid Business Pack 1.4 2P | G8: 160659 | H8: Veículo sofreu uma colisão e capotamento. | I8: 45879 | J8: Isabelli | K8: Sinistro | L8: Corretiva | M8: Aprovado | N8: 13750 | O8: 13750 | P8: =VLOOKUP(Tabela1[[#This Row],[Placa]],'Base Cadastro '!A:M,13,FALSE) -> SMG5 | Q8: MERCADO LIVRE | R8: Sinistro | S8: Em diagnóstico | U8: =IFERROR(DATEDIF(Tabela1[[#This Row],[Data Agenda]],Tabela1[[#This Row],[Liberado]],"D"),DATEDIF(Tabela1[[#This Row],[Data Agenda]],TODAY(),"D")) -> 99 | V8: =IF(Tabela1[[#This Row],[D+Manut]]<=2,"Dentro do Prazo","Fora do Prazo") -> Fora do Prazo | W8: GR Car | X8: CAMILA | Y8: Ago | Z8: =VLOOKUP(Tabela1[[#This Row],[Placa]],DadosViagem5[[Placa]:[Base]],11,FALSE) -> SC (POÇOS DE CALDAS) SMG5
E9: RVQ2D86 | F9: =IFERROR(VLOOKUP(Tabela1[[#This Row],[Placa]],'Base Cadastro '!A:B,2,FALSE),"Correção de cadastro") -> MASTER FURGAO L1 | G9: N/E | H9: Motor | I9: 45677 | J9: Carla I. | K9: Manutenção | L9: Corretiva | M9: Aprovado | P9: =VLOOKUP(Tabela1[[#This Row],[Placa]],'Base Cadastro '!A:M,13,FALSE) -> SSP16 | Q9: MERCADO LIVRE | R9: Motor | S9: 45978 | U9: =IFERROR(DATEDIF(Tabela1[[#This Row],[Data Agenda]],Tabela1[[#This Row],[Liberado]],"D"),DATEDIF(Tabela1[[#This Row],[Data Agenda]],TODAY(),"D")) -> 301 | V9: =IF(Tabela1[[#This Row],[D+Manut]]<=2,"Dentro do Prazo","Fora do Prazo") -> Fora do Prazo | W9: Estacionamento da Coca/MuriTruck | X9: CAMILA | Y9: Jan | Z9: =VLOOKUP(Tabela1[[#This Row],[Placa]],DadosViagem5[[Placa]:[Base]],11,FALSE) -> SC (CARAGUATATUBA) SSP16
C10: Sim | E10: QPC5I33 | F10: =IFERROR(VLOOKUP(Tabela1[[#This Row],[Placa]],'Base Cadastro '!A:B,2,FALSE),"Correção de cadastro") -> MASTER FURGAO L1 | G10: N/E | H10: Veículo sofreu uma colisão frontal, montando já libera hoje. | I10: 45793 | J10: Isabelli | K10: Sinistro | L10: Corretiva | M10: Aprovado | N10: 5304.2 | O10: 5304.2 | P10: =VLOOKUP(Tabela1[[#This Row],[Placa]],'Base Cadastro '!A:M,13,FALSE) -> SSC3 | Q10: MERCADO LIVRE | R10: Sinistro | S10: 45982 | U10: =IFERROR(DATEDIF(Tabela1[[#This Row],[Data Agenda]],Tabela1[[#This Row],[Liberado]],"D"),DATEDIF(Tabela1[[#This Row],[Data Agenda]],TODAY(),"D")) -> 185 | V10: =IF(Tabela1[[#This Row],[D+Manut]]<=2,"Dentro do Prazo","Fora do Prazo") -> Fora do Prazo | W10: FSP | X10: GABRIELI | Y10: Set | Z10: =VLOOKUP(Tabela1[[#This Row],[Placa]],DadosViagem5[[Placa]:[Base]],11,FALSE) -> SC (BLUMENAU) SSC3
C11: Sim | E11: SVT9G70 | F11: =IFERROR(VLOOKUP(Tabela1[[#This Row],[Placa]],'Base Cadastro '!A:B,2,FALSE),"Correção de cadastro") -> MASTER FURGAO L1 | G11: 47465 | H11: Colisão dianteira grave. Aguardando peça já solicitadas, que chegrarão dia 15/10/2025 | I11: 45820 | J11: Isabelli | K11: Sinistro | L11: Corretiva | M11: Aprovado | N11: 46000 | O11: 29429 | P11: =VLOOKUP(Tabela1[[#This Row],[Placa]],'Base Cadastro '!A:M,13,FALSE) -> EPR6 | Q11: MERCADO LIVRE | R11: Sinistro | S11: 45980 | U11: =IFERROR(DATEDIF(Tabela1[[#This Row],[Data Agenda]],Tabela1[[#This Row],[Liberado]],"D"),DATEDIF(Tabela1[[#This Row],[Data Agenda]],TODAY(),"D")) -> 158 | V11: =IF(Tabela1[[#This Row],[D+Manut]]<=2,"Dentro do Prazo","Fora do Prazo") -> Fora do Prazo | W11: FSP | X11: ALINE | Y11: Set | Z11: =VLOOKUP(Tabela1[[#This Row],[Placa]],DadosViagem5[[Placa]:[Base]],11,FALSE) -> XPT (SAO MATEUS DO SUL) EPR6/SPR7
E12: SGI8I22 | F12: =IFERROR(VLOOKUP(Tabela1[[#This Row],[Placa]],'Base Cadastro '!A:B,2,FALSE),"Correção de cadastro") -> TRANSIT FURGÃO | G12: 24826 | H12: Colisão frontal, efetuando nova cotação na RRW. | I12: 45836 | J12: Vinicius | K12: Sinistro | L12: Corretiva | M12: Aprovado | N12: 5000 | O12: 5000 | P12: =VLOOKUP(Tabela1[[#This Row],[Placa]],'Base Cadastro '!A:M,13,FALSE) -> SSP30 | Q12: MERCADO LIVRE | R12: Sinistro | S12: 45980 | U12: =IFERROR(DATEDIF(Tabela1[[#This Row],[Data Agenda]],Tabela1[[#This Row],[Liberado]],"D"),DATEDIF(Tabela1[[#This Row],[Data Agenda]],TODAY(),"D")) -> 142 | V12: =IF(Tabela1[[#This Row],[D+Manut]]<=2,"Dentro do Prazo","Fora do Prazo") -> Fora do Prazo | W12: Helena Maria | X12: Claudia | Y12: Jun | Z12: =VLOOKUP(Tabela1[[#This Row],[Placa]],DadosViagem5[[Placa]:[Base]],11,FALSE) -> SC (MEGA GUARULHOS) SSP30
E13: SFW2B76 | F13: =IFERROR(VLOOKUP(Tabela1[[#This Row],[Placa]],'Base Cadastro '!A:B,2,FALSE),"Correção de cadastro") -> TRANSIT FURGÃO | G13: 17296 | H13: Colisão traseira, coluna do baú. | I13: 45789 | J13: Vinicius | K13: Sinistro | L13: Corretiva | M13: Aprovado | P13: =VLOOKUP(Tabela1[[#This Row],[Placa]],'Base Cadastro '!A:M,13,FALSE) -> SSC5 | Q13: MERCADO LIVRE | R13: Sinistro | S13: 46019 | U13: =IFERROR(DATEDIF(Tabela1[[#This Row],[Data Agenda]],Tabela1[[#This Row],[Liberado]],"D"),DATEDIF(Tabela1[[#This Row],[Data Agenda]],TODAY(),"D")) -> 189 | V13: =IF(Tabela1[[#This Row],[D+Manut]]<=2,"Dentro do Prazo","Fora do Prazo") -> Fora do Prazo | W13: Safety Car | X13: Alessandra | Y13: Set | Z13: =VLOOKUP(Tabela1[[#This Row],[Placa]],DadosViagem5[[Placa]:[Base]],11,FALSE) -> SC (CRICIUMA) SSC5
C14: Sim | E14: GFB0H75 | F14: =IFERROR(VLOOKUP(Tabela1[[#This Row],[Placa]],'Base Cadastro '!A:B,2,FALSE),"Correção de cadastro") -> Sprinter 313 | G14: 79000 | H14: Aguardando Aprovação serviço de bico injetores | I14: 45681 | J14: Luana | K14: Manutenção | L14: Corretiva | M14: Aprovado | N14: 23000 | O14: 17000 | P14: =VLOOKUP(Tabela1[[#This Row],[Placa]],'Base Cadastro '!A:M,13,FALSE) -> SSP28 | Q14: MERCADO LIVRE | R14: Em Manutenção | S14: 45982 | U14: =IFERROR(DATEDIF(Tabela1[[#This Row],[Data Agenda]],Tabela1[[#This Row],[Liberado]],"D"),DATEDIF(Tabela1[[#This Row],[Data Agenda]],TODAY(),"D")) -> 297 | V14: =IF(Tabela1[[#This Row],[D+Manut]]<=2,"Dentro do Prazo","Fora do Prazo") -> Fora do Prazo | W14: Injemec | X14: JOAO VITOR | Y14: Jan | Z14: =VLOOKUP(Tabela1[[#This Row],[Placa]],DadosViagem5[[Placa]:[Base]],11,FALSE) -> SC (JALES) SSP28
E15: SGH0H20 | F15: =IFERROR(VLOOKUP(Tabela1[[#This Row],[Placa]],'Base Cadastro '!A:B,2,FALSE),"Correção de cadastro") -> TRANSIT FURGÃO | G15: 66248 | H15: Bomba e Bico Injetor | I15: 45943 | J15: Hillary | K15: Manutenção | L15: Corretiva | M15: Aprovado | P15: =VLOOKUP(Tabela1[[#This Row],[Placa]],'Base Cadastro '!A:M,13,FALSE) -> SRS10 | Q15: MERCADO LIVRE | R15: Em Manutenção | S15: 45978 | U15: =IFERROR(DATEDIF(Tabela1[[#This Row],[Data Agenda]],Tabela1[[#This Row],[Liberado]],"D"),DATEDIF(Tabela1[[#This Row],[Data Agenda]],TODAY(),"D")) -> 35 | V15: =IF(Tabela1[[#This Row],[D+Manut]]<=2,"Dentro do Prazo","Fora do Prazo") -> Fora do Prazo | W15: Ford Amazon Novo Hamburgo | X15: FERNANDA | Y15: Out | Z15: =VLOOKUP(Tabela1[[#This Row],[Placa]],DadosViagem5[[Placa]:[Base]],11,FALSE) -> SC (LAJEADO) SRS10
E16: SGH8H56 | F16: =IFERROR(VLOOKUP(Tabela1[[#This Row],[Placa]],'Base Cadastro '!A:B,2,FALSE),"Correção de cadastro") -> TRANSIT FURGÃO | G16: 97608 | H16: Bomba e Bico Injetor | I16: 45943 | J16: Hillary | K16: Manutenção | L16: Corretiva | M16: Aprovado | P16: =VLOOKUP(Tabela1[[#This Row],[Placa]],'Base Cadastro '!A:M,13,FALSE) -> SRS10 | Q16: MERCADO LIVRE | R16: Em Manutenção | S16: 45978 | U16: =IFERROR(DATEDIF(Tabela1[[#This Row],[Data Agenda]],Tabela1[[#This Row],[Liberado]],"D"),DATEDIF(Tabela1[[#This Row],[Data Agenda]],TODAY(),"D")) -> 35 | V16: =IF(Tabela1[[#This Row],[D+Manut]]<=2,"Dentro do Prazo","Fora do Prazo") -> Fora do Prazo | W16: Ford Lajeado | X16: FERNANDA | Y16: Out | Z16: =VLOOKUP(Tabela1[[#This Row],[Placa]],DadosViagem5[[Placa]:[Base]],11,FALSE) -> SC (LAJEADO) SRS10
E17: SFT5A73 | F17: =IFERROR(VLOOKUP(Tabela1[[#This Row],[Placa]],'Base Cadastro '!A:B,2,FALSE),"Correção de cadastro") -> TRANSIT FURGÃO | G17: 55792 | H17: Motorista colidiu a nossa Van em um poste por desatenção | I17: 45933 | J17: Isabelli | K17: Sinistro | L17: Corretiva | M17: Aprovado | N17: 2400 | O17: 2400 | P17: =VLOOKUP(Tabela1[[#This Row],[Placa]],'Base Cadastro '!A:M,13,FALSE) -> SSP22 | Q17: MERCADO LIVRE | R17: Sinistro | S17: 45982 | U17: =IFERROR(DATEDIF(Tabela1[[#This Row],[Data Agenda]],Tabela1[[#This Row],[Liberado]],"D"),DATEDIF(Tabela1[[#This Row],[Data Agenda]],TODAY(),"D")) -> 45 | V17: =IF(Tabela1[[#This Row],[D+Manut]]<=2,"Dentro do Prazo","Fora do Prazo") -> Fora do Prazo | W17: Funilaria Athaide | X17: MAURICIO | Y17: Out | Z17: =VLOOKUP(Tabela1[[#This Row],[Placa]],DadosViagem5[[Placa]:[Base]],11,FALSE) -> SC (SAO CARLOS) SSP22
E18: RNP6E45 | F18: =IFERROR(VLOOKUP(Tabela1[[#This Row],[Placa]],'Base Cadastro '!A:B,2,FALSE),"Correção de cadastro") -> Master Furgão 8m³ | G18: 120931 | H18: Motor | I18: 45825 | J18: Natallia | K18: Manutenção | L18: Corretiva | M18: Aprovado | P18: =VLOOKUP(Tabela1[[#This Row],[Placa]],'Base Cadastro '!A:M,13,FALSE) -> SRS8 | Q18: MERCADO LIVRE | R18: Motor | S18: Aguardando pagamento | U18: =IFERROR(DATEDIF(Tabela1[[#This Row],[Data Agenda]],Tabela1[[#This Row],[Liberado]],"D"),DATEDIF(Tabela1[[#This Row],[Data Agenda]],TODAY(),"D")) -> 153 | V18: =IF(Tabela1[[#This Row],[D+Manut]]<=2,"Dentro do Prazo","Fora do Prazo") -> Fora do Prazo | W18: Safety Car | X18: ALESSANDRA | Y18: Jun | Z18: =VLOOKUP(Tabela1[[#This Row],[Placa]],DadosViagem5[[Placa]:[Base]],11,FALSE) -> SC (SAPUCAIA) SRS8
E19: GJG8C81 | F19: =IFERROR(VLOOKUP(Tabela1[[#This Row],[Placa]],'Base Cadastro '!A:B,2,FALSE),"Correção de cadastro") -> Sprinter 313 | G19: N/D | H19: 2° via de chave, motorista passou por cima da mesma. | I19: 45958 | J19: Vinicius | K19: Sinistro | L19: Corretiva | M19: Aprovado | N19: 0 | O19: 0 | P19: =VLOOKUP(Tabela1[[#This Row],[Placa]],'Base Cadastro '!A:M,13,FALSE) -> FMS09 | Q19: SHOPEE | R19: Sinistro | S19: 45982 | U19: =IFERROR(DATEDIF(Tabela1[[#This Row],[Data Agenda]],Tabela1[[#This Row],[Liberado]],"D"),DATEDIF(Tabela1[[#This Row],[Data Agenda]],TODAY(),"D")) -> 20 | V19: =IF(Tabela1[[#This Row],[D+Manut]]<=2,"Dentro do Prazo","Fora do Prazo") -> Fora do Prazo | W19: Denigris (São Bernardo do Campo) | X19: Kimberlly | Y19: Out | Z19: =VLOOKUP(Tabela1[[#This Row],[Placa]],DadosViagem5[[Placa]:[Base]],11,FALSE) -> FMS09 SÃO PAULO (SP)
E20: RUM2B60 | F20: =IFERROR(VLOOKUP(Tabela1[[#This Row],[Placa]],'Base Cadastro '!A:B,2,FALSE),"Correção de cadastro") -> Fiorino Endurance Evo 1.4 2P | G20: 206871 | H20: Suspensão, Freio dianteiro | I20: 45972 | J20: Luana | K20: Manutenção | L20: Corretiva | M20: Aprovado | P20: =VLOOKUP(Tabela1[[#This Row],[Placa]],'Base Cadastro '!A:M,13,FALSE) -> SSP28 | Q20: MERCADO LIVRE | R20: Em Manutenção | S20: 45979 | U20: =IFERROR(DATEDIF(Tabela1[[#This Row],[Data Agenda]],Tabela1[[#This Row],[Liberado]],"D"),DATEDIF(Tabela1[[#This Row],[Data Agenda]],TODAY(),"D")) -> 6 | V20: =IF(Tabela1[[#This Row],[D+Manut]]<=2,"Dentro do Prazo","Fora do Prazo") -> Fora do Prazo | W20: Injemec | X20: JOAO VITOR | Y20: Nov | Z20: =VLOOKUP(Tabela1[[#This Row],[Placa]],DadosViagem5[[Placa]:[Base]],11,FALSE) -> SC (JALES) SSP28
D21: 6797882 | E21: SDQ2A43 | F21: =IFERROR(VLOOKUP(Tabela1[[#This Row],[Placa]],'Base Cadastro '!A:B,2,FALSE),"Correção de cadastro") -> Kangoo Z.E. MAXI 5 Lugares 2P | G21: 78322 | H21: Alinhamento / Balanceamento, suspensão e pneus | I21: 45964 | J21: Carla I. | K21: Manutenção | L21: Corretiva | M21: Negociando | P21: =VLOOKUP(Tabela1[[#This Row],[Placa]],'Base Cadastro '!A:M,13,FALSE) -> SSP15 | Q21: MERCADO LIVRE | R21: Em Manutenção | S21: 45979 | U21: =IFERROR(DATEDIF(Tabela1[[#This Row],[Data Agenda]],Tabela1[[#This Row],[Liberado]],"D"),DATEDIF(Tabela1[[#This Row],[Data Agenda]],TODAY(),"D")) -> 14 | V21: =IF(Tabela1[[#This Row],[D+Manut]]<=2,"Dentro do Prazo","Fora do Prazo") -> Fora do Prazo | W21: WM RENOVADORA (Localiza) | X21: NATANAEL | Y21: Out. | Z21: =VLOOKUP(Tabela1[[#This Row],[Placa]],DadosViagem5[[Placa]:[Base]],11,FALSE) -> SC (SANTOS) SSP15
D22: 6795801 | E22: SDQ3A32 | F22: =IFERROR(VLOOKUP(Tabela1[[#This Row],[Placa]],'Base Cadastro '!A:B,2,FALSE),"Correção de cadastro") -> Kangoo Z.E. MAXI 5 Lugares 2P | G22: 60490 | H22: Manunteção de rotina, preventiva | I22: 45968 | J22: Carla I. | K22: Manutenção | L22: Preventiva | M22: Aprovado | P22: =VLOOKUP(Tabela1[[#This Row],[Placa]],'Base Cadastro '!A:M,13,FALSE) -> SSP4 | Q22: MERCADO LIVRE | R22: Em Manutenção | S22: 45979 | U22: =IFERROR(DATEDIF(Tabela1[[#This Row],[Data Agenda]],Tabela1[[#This Row],[Liberado]],"D"),DATEDIF(Tabela1[[#This Row],[Data Agenda]],TODAY(),"D")) -> 10 | V22: =IF(Tabela1[[#This Row],[D+Manut]]<=2,"Dentro do Prazo","Fora do Prazo") -> Fora do Prazo | W22: OFICINA DO BETO (Localiza) | X22: Marcio | Y22: Nov | Z22: =VLOOKUP(Tabela1[[#This Row],[Placa]],DadosViagem5[[Placa]:[Base]],11,FALSE) -> SC (RIBEIRAO PRETO) SSP4
E23: SGF8I65 | F23: =IFERROR(VLOOKUP(Tabela1[[#This Row],[Placa]],'Base Cadastro '!A:B,2,FALSE),"Correção de cadastro") -> TRANSIT CHASSI | G23: 32452 | H23: "Vai pra VIAFOR hoje, aguardando o guincho para levar, veículo para troca de pneus, freios, troca de óleo, está com alguma coisa fazendo muito barulho na roda dianteira, só no guincho para seguir. " | I23: 45911 | J23: Hillary | K23: Manutenção | L23: Corretiva | M23: Negociando | P23: =VLOOKUP(Tabela1[[#This Row],[Placa]],'Base Cadastro '!A:M,13,FALSE) -> SES1 | Q23: MERCADO LIVRE | R23: Em Manutenção | S23: 45979 | U23: =IFERROR(DATEDIF(Tabela1[[#This Row],[Data Agenda]],Tabela1[[#This Row],[Liberado]],"D"),DATEDIF(Tabela1[[#This Row],[Data Agenda]],TODAY(),"D")) -> 67 | V23: =IF(Tabela1[[#This Row],[D+Manut]]<=2,"Dentro do Prazo","Fora do Prazo") -> Fora do Prazo | W23: KM Auto Center | X23: JOÃO | Y23: Set | Z23: =VLOOKUP(Tabela1[[#This Row],[Placa]],DadosViagem5[[Placa]:[Base]],11,FALSE) -> SC (VITORIA) SES1
E24: SGF9B05 | F24: =IFERROR(VLOOKUP(Tabela1[[#This Row],[Placa]],'Base Cadastro '!A:B,2,FALSE),"Correção de cadastro") -> TRANSIT CHASSI | G24: 39260 | H24: Veículo vai para a concessionaria na data 06/10 vai fazer Pneu, óleo, filtros, freios... | I24: 45897 | J24: Hillary | K24: Manutenção | L24: Corretiva | M24: Negociando | N24: 5590.14 | P24: =VLOOKUP(Tabela1[[#This Row],[Placa]],'Base Cadastro '!A:M,13,FALSE) -> SES1 | Q24: MERCADO LIVRE | R24: Em Manutenção | S24: 45979 | U24: =IFERROR(DATEDIF(Tabela1[[#This Row],[Data Agenda]],Tabela1[[#This Row],[Liberado]],"D"),DATEDIF(Tabela1[[#This Row],[Data Agenda]],TODAY(),"D")) -> 81 | V24: =IF(Tabela1[[#This Row],[D+Manut]]<=2,"Dentro do Prazo","Fora do Prazo") -> Fora do Prazo | W24: KM Auto Center | X24: JOÃO | Y24: Ago | Z24: =VLOOKUP(Tabela1[[#This Row],[Placa]],DadosViagem5[[Placa]:[Base]],11,FALSE) -> SC (VITORIA) SES1
E25: RNF2B91 | F25: =IFERROR(VLOOKUP(Tabela1[[#This Row],[Placa]],'Base Cadastro '!A:B,2,FALSE),"Correção de cadastro") -> MASTER FURGAO L1 | G25: 130018 | H25: Funilaria traseira | I25: 45898 | J25: Isabelli | K25: Sinistro | L25: Corretiva | M25: Aprovado | N25: 3000 | O25: 2600 | P25: =VLOOKUP(Tabela1[[#This Row],[Placa]],'Base Cadastro '!A:M,13,FALSE) -> SSP5 | Q25: MERCADO LIVRE | R25: Sinistro | S25: 45980 | U25: =IFERROR(DATEDIF(Tabela1[[#This Row],[Data Agenda]],Tabela1[[#This Row],[Liberado]],"D"),DATEDIF(Tabela1[[#This Row],[Data Agenda]],TODAY(),"D")) -> 80 | V25: =IF(Tabela1[[#This Row],[D+Manut]]<=2,"Dentro do Prazo","Fora do Prazo") -> Fora do Prazo | W25: Oficina Vieira | X25: MARCELO/ISLENE/ERIVELTON | Y25: Ago | Z25: =VLOOKUP(Tabela1[[#This Row],[Placa]],DadosViagem5[[Placa]:[Base]],11,FALSE) -> SC (ARENA BARUERI) SSP5
E26: RUX2B50 | F26: =IFERROR(VLOOKUP(Tabela1[[#This Row],[Placa]],'Base Cadastro '!A:B,2,FALSE),"Correção de cadastro") -> Partner Rapid Business Pack 1.4 2P | G26: 54096 | H26: Veículo realizando o reparo no Cambio- Apos processo de manutenção a mesma vai ser desmobilizada 13/11 | I26: 45730 | J26: Julia | K26: Manutenção | L26: Corretiva | M26: Aprovado | P26: =VLOOKUP(Tabela1[[#This Row],[Placa]],'Base Cadastro '!A:M,13,FALSE) -> SMR1 | Q26: MERCADO LIVRE | R26: Em Manutenção | S26: 45980 | U26: =IFERROR(DATEDIF(Tabela1[[#This Row],[Data Agenda]],Tabela1[[#This Row],[Liberado]],"D"),DATEDIF(Tabela1[[#This Row],[Data Agenda]],TODAY(),"D")) -> 248 | V26: =IF(Tabela1[[#This Row],[D+Manut]]<=2,"Dentro do Prazo","Fora do Prazo") -> Fora do Prazo | W26: GP Auto Center | X26: MICAEL MARCOS | Y26: Mar | Z26: =VLOOKUP(Tabela1[[#This Row],[Placa]],DadosViagem5[[Placa]:[Base]],11,FALSE) -> SC (CUIABA) SMR1
D27: 6795781 | E27: RHU2D75 | F27: =IFERROR(VLOOKUP(Tabela1[[#This Row],[Placa]],'Base Cadastro '!A:B,2,FALSE),"Correção de cadastro") -> JAC iEV1200T AT 4x2 2P | G27: 49899 | H27: Pane Eletrica - Placa pesada - Este caminhão está em teste de módulos das bateiras, onde cada módulo tem diversas células (como se fosse um conjunto de pilhas 10/11/2025 | I27: 45959 | J27: Carla I. | K27: Manutenção | L27: Corretiva | M27: Aprovado | P27: =VLOOKUP(Tabela1[[#This Row],[Placa]],'Base Cadastro '!A:M,13,FALSE) -> SSP30 | Q27: MERCADO LIVRE | R27: Em Manutenção | S27: 45980 | U27: =IFERROR(DATEDIF(Tabela1[[#This Row],[Data Agenda]],Tabela1[[#This Row],[Liberado]],"D"),DATEDIF(Tabela1[[#This Row],[Data Agenda]],TODAY(),"D")) -> 19 | V27: =IF(Tabela1[[#This Row],[D+Manut]]<=2,"Dentro do Prazo","Fora do Prazo") -> Fora do Prazo | W27: TICKET LOG MANUTENCA (Localiza) | X27: Claudia | Y27: Out | Z27: =VLOOKUP(Tabela1[[#This Row],[Placa]],DadosViagem5[[Placa]:[Base]],11,FALSE) -> SC (MEGA GUARULHOS) SSP30
C28: Sim | E28: RUX2B54 | F28: =IFERROR(VLOOKUP(Tabela1[[#This Row],[Placa]],'Base Cadastro '!A:B,2,FALSE),"Correção de cadastro") -> Partner Rapid Business Pack 1.4 2P | G28: N/E | H28: 16/07-Motor Na Retifica 05/05 - Junta Cabeçote agaurdando aprovaçã andre 26/09- Apos processo de manutenção a mesma vai ser desmobilizada 13/11 | I28: 45704 | J28: Julia | K28: Manutenção | L28: Corretiva | M28: Aprovado | N28: 27000 | O28: 15000 | P28: =VLOOKUP(Tabela1[[#This Row],[Placa]],'Base Cadastro '!A:M,13,FALSE) -> SMR1 | Q28: MERCADO LIVRE | R28: Motor | S28: 45980 | U28: =IFERROR(DATEDIF(Tabela1[[#This Row],[Data Agenda]],Tabela1[[#This Row],[Liberado]],"D"),DATEDIF(Tabela1[[#This Row],[Data Agenda]],TODAY(),"D")) -> 274 | V28: =IF(Tabela1[[#This Row],[D+Manut]]<=2,"Dentro do Prazo","Fora do Prazo") -> Fora do Prazo | W28: GP Auto Center | X28: MICAEL MARCOS | Y28: Fev | Z28: =VLOOKUP(Tabela1[[#This Row],[Placa]],DadosViagem5[[Placa]:[Base]],11,FALSE) -> SC (CUIABA) SMR1
D29: 6794461 | E29: RHW0D75 | F29: =IFERROR(VLOOKUP(Tabela1[[#This Row],[Placa]],'Base Cadastro '!A:B,2,FALSE),"Correção de cadastro") -> E-Jumpy Furgão 2P | G29: 57896 | H29: Pane eletrica; Bateria; | I29: 45944 | J29: Julia | K29: Manutenção | L29: Corretiva | M29: Aprovado | P29: =VLOOKUP(Tabela1[[#This Row],[Placa]],'Base Cadastro '!A:M,13,FALSE) -> SBA1 | Q29: MERCADO LIVRE | R29: C/Reserva | S29: 45980 | U29: =IFERROR(DATEDIF(Tabela1[[#This Row],[Data Agenda]],Tabela1[[#This Row],[Liberado]],"D"),DATEDIF(Tabela1[[#This Row],[Data Agenda]],TODAY(),"D")) -> 34 | V29: =IF(Tabela1[[#This Row],[D+Manut]]<=2,"Dentro do Prazo","Fora do Prazo") -> Fora do Prazo | W29: Gaulesa Iguatemi (Localiza) | X29: UEBERT | Y29: Out | Z29: =VLOOKUP(Tabela1[[#This Row],[Placa]],DadosViagem5[[Placa]:[Base]],11,FALSE) -> SC (BAHIA SALVADOR) SBA1
D30: 6789331 | E30: SDT9F97 | F30: =IFERROR(VLOOKUP(Tabela1[[#This Row],[Placa]],'Base Cadastro '!A:B,2,FALSE),"Correção de cadastro") -> E-Jumpy Furgão 2P | G30: 22935 | H30: Pane elétrica | I30: 45940 | J30: Natallia | K30: Manutenção | L30: Corretiva | M30: Aprovado | P30: =VLOOKUP(Tabela1[[#This Row],[Placa]],'Base Cadastro '!A:M,13,FALSE) -> SRS1 | Q30: MERCADO LIVRE | R30: C/Reserva | S30: 45980 | U30: =IFERROR(DATEDIF(Tabela1[[#This Row],[Data Agenda]],Tabela1[[#This Row],[Liberado]],"D"),DATEDIF(Tabela1[[#This Row],[Data Agenda]],TODAY(),"D")) -> 38 | V30: =IF(Tabela1[[#This Row],[D+Manut]]<=2,"Dentro do Prazo","Fora do Prazo") -> Fora do Prazo | W30: PEUGEOT LYON (Localiza) | X30: EVAILTON | Y30: Out | Z30: =VLOOKUP(Tabela1[[#This Row],[Placa]],DadosViagem5[[Placa]:[Base]],11,FALSE) -> SC (PORTO ALEGRE) SRS1
D31: 6794451 | E31: SDP9I99 | F31: =IFERROR(VLOOKUP(Tabela1[[#This Row],[Placa]],'Base Cadastro '!A:B,2,FALSE),"Correção de cadastro") -> E-Jumpy Furgão 2P | G31: 10202 | H31: Pane Eletrica; bateria | I31: 45953 | J31: Julia | K31: Manutenção | L31: Corretiva | M31: Aprovado | P31: =VLOOKUP(Tabela1[[#This Row],[Placa]],'Base Cadastro '!A:M,13,FALSE) -> SBA1 | Q31: MERCADO LIVRE | R31: C/Reserva | S31: 45980 | U31: =IFERROR(DATEDIF(Tabela1[[#This Row],[Data Agenda]],Tabela1[[#This Row],[Liberado]],"D"),DATEDIF(Tabela1[[#This Row],[Data Agenda]],TODAY(),"D")) -> 25 | V31: =IF(Tabela1[[#This Row],[D+Manut]]<=2,"Dentro do Prazo","Fora do Prazo") -> Fora do Prazo | W31: Gaulesa Iguatemi (Localiza) | X31: TIAGO | Y31: Out | Z31: =VLOOKUP(Tabela1[[#This Row],[Placa]],DadosViagem5[[Placa]:[Base]],11,FALSE) -> SC (BAHIA SALVADOR) SBA1
D32: 6794202 | E32: RHW0D47 | F32: =IFERROR(VLOOKUP(Tabela1[[#This Row],[Placa]],'Base Cadastro '!A:B,2,FALSE),"Correção de cadastro") -> E-Jumpy Furgão 2P | G32: 88701 | H32: Pane Eletrica; bateria | I32: 45953 | J32: Julia | K32: Manutenção | L32: Corretiva | M32: Aprovado | P32: =VLOOKUP(Tabela1[[#This Row],[Placa]],'Base Cadastro '!A:M,13,FALSE) -> SBA1 | Q32: MERCADO LIVRE | R32: C/Reserva | S32: 45980 | U32: =IFERROR(DATEDIF(Tabela1[[#This Row],[Data Agenda]],Tabela1[[#This Row],[Liberado]],"D"),DATEDIF(Tabela1[[#This Row],[Data Agenda]],TODAY(),"D")) -> 25 | V32: =IF(Tabela1[[#This Row],[D+Manut]]<=2,"Dentro do Prazo","Fora do Prazo") -> Fora do Prazo | W32: Gaulesa Iguatemi (Localiza) | X32: TIAGO | Y32: Out | Z32: =VLOOKUP(Tabela1[[#This Row],[Placa]],DadosViagem5[[Placa]:[Base]],11,FALSE) -> SC (BAHIA SALVADOR) SBA1
D33: 6794458 | E33: RHW0D84 | F33: =IFERROR(VLOOKUP(Tabela1[[#This Row],[Placa]],'Base Cadastro '!A:B,2,FALSE),"Correção de cadastro") -> E-Jumpy Furgão 2P | G33: 55810 | H33: Pane Eletrica; bateria | I33: 45953 | J33: Julia | K33: Manutenção | L33: Corretiva | M33: Aprovado | P33: =VLOOKUP(Tabela1[[#This Row],[Placa]],'Base Cadastro '!A:M,13,FALSE) -> SBA1 | Q33: MERCADO LIVRE | R33: C/Reserva | S33: 45980 | U33: =IFERROR(DATEDIF(Tabela1[[#This Row],[Data Agenda]],Tabela1[[#This Row],[Liberado]],"D"),DATEDIF(Tabela1[[#This Row],[Data Agenda]],TODAY(),"D")) -> 25 | V33: =IF(Tabela1[[#This Row],[D+Manut]]<=2,"Dentro do Prazo","Fora do Prazo") -> Fora do Prazo | W33: Gaulesa Iguatemi (Localiza) | X33: TIAGO | Y33: Out | Z33: =VLOOKUP(Tabela1[[#This Row],[Placa]],DadosViagem5[[Placa]:[Base]],11,FALSE) -> SC (BAHIA SALVADOR) SBA1
D34: 6794199 | E34: SDP9J01 | F34: =IFERROR(VLOOKUP(Tabela1[[#This Row],[Placa]],'Base Cadastro '!A:B,2,FALSE),"Correção de cadastro") -> E-Jumpy Furgão 2P | G34: 73518 | H34: Pane Eletrica; bateria | I34: 45953 | J34: Julia | K34: Manutenção | L34: Corretiva | M34: Aprovado | P34: =VLOOKUP(Tabela1[[#This Row],[Placa]],'Base Cadastro '!A:M,13,FALSE) -> SBA1 | Q34: MERCADO LIVRE | R34: C/Reserva | S34: 45980 | U34: =IFERROR(DATEDIF(Tabela1[[#This Row],[Data Agenda]],Tabela1[[#This Row],[Liberado]],"D"),DATEDIF(Tabela1[[#This Row],[Data Agenda]],TODAY(),"D")) -> 25 | V34: =IF(Tabela1[[#This Row],[D+Manut]]<=2,"Dentro do Prazo","Fora do Prazo") -> Fora do Prazo | W34: Gaulesa Iguatemi (Localiza) | X34: TIAGO | Y34: Out | Z34: =VLOOKUP(Tabela1[[#This Row],[Placa]],DadosViagem5[[Placa]:[Base]],11,FALSE) -> SC (BAHIA SALVADOR) SBA1
D35: 6794200 | E35: RHW0D37 | F35: =IFERROR(VLOOKUP(Tabela1[[#This Row],[Placa]],'Base Cadastro '!A:B,2,FALSE),"Correção de cadastro") -> E-Jumpy Furgão 2P | G35: 63500 | H35: Pane Eletrica; bateria | I35: 45953 | J35: Julia | K35: Manutenção | L35: Corretiva | M35: Aprovado | P35: =VLOOKUP(Tabela1[[#This Row],[Placa]],'Base Cadastro '!A:M,13,FALSE) -> SBA1 | Q35: MERCADO LIVRE | R35: C/Reserva | S35: 45980 | U35: =IFERROR(DATEDIF(Tabela1[[#This Row],[Data Agenda]],Tabela1[[#This Row],[Liberado]],"D"),DATEDIF(Tabela1[[#This Row],[Data Agenda]],TODAY(),"D")) -> 25 | V35: =IF(Tabela1[[#This Row],[D+Manut]]<=2,"Dentro do Prazo","Fora do Prazo") -> Fora do Prazo | W35: Gaulesa Iguatemi (Localiza) | X35: TIAGO | Y35: Out | Z35: =VLOOKUP(Tabela1[[#This Row],[Placa]],DadosViagem5[[Placa]:[Base]],11,FALSE) -> SC (BAHIA SALVADOR) SBA1
D36: 6792618 | E36: SDQ2A99 | F36: =IFERROR(VLOOKUP(Tabela1[[#This Row],[Placa]],'Base Cadastro '!A:B,2,FALSE),"Correção de cadastro") -> Kangoo Z.E. MAXI 5 Lugares 2P | G36: 66899 | H36: Bateria de rodagem | I36: 45937 | J36: Natallia | K36: Manutenção | L36: Corretiva | M36: Aprovado | P36: =VLOOKUP(Tabela1[[#This Row],[Placa]],'Base Cadastro '!A:M,13,FALSE) -> SSC2 | Q36: MERCADO LIVRE | R36: C/Reserva | S36: 45982 | U36: =IFERROR(DATEDIF(Tabela1[[#This Row],[Data Agenda]],Tabela1[[#This Row],[Liberado]],"D"),DATEDIF(Tabela1[[#This Row],[Data Agenda]],TODAY(),"D")) -> 41 | V36: =IF(Tabela1[[#This Row],[D+Manut]]<=2,"Dentro do Prazo","Fora do Prazo") -> Fora do Prazo | W36: AUTOMEGA (Localiza) | X36: CARLOS SELL | Y36: Out | Z36: =VLOOKUP(Tabela1[[#This Row],[Placa]],DadosViagem5[[Placa]:[Base]],11,FALSE) -> SC (FLORIANOPOLIS) SSC2
E37: SGH8H53 | F37: =IFERROR(VLOOKUP(Tabela1[[#This Row],[Placa]],'Base Cadastro '!A:B,2,FALSE),"Correção de cadastro") -> TRANSIT FURGÃO | G37: 50744 | H37: Revisão(Pastilha de Freio) | I37: 45965 | J37: Hillary | K37: Manutenção | L37: Corretiva | M37: Negociando | P37: =VLOOKUP(Tabela1[[#This Row],[Placa]],'Base Cadastro '!A:M,13,FALSE) -> SSC3 | Q37: MERCADO LIVRE | R37: Em Manutenção | S37: 45980 | U37: =IFERROR(DATEDIF(Tabela1[[#This Row],[Data Agenda]],Tabela1[[#This Row],[Liberado]],"D"),DATEDIF(Tabela1[[#This Row],[Data Agenda]],TODAY(),"D")) -> 13 | V37: =IF(Tabela1[[#This Row],[D+Manut]]<=2,"Dentro do Prazo","Fora do Prazo") -> Fora do Prazo | W37: Ford AutoPlus | X37: Gabrieli | Y37: Nov | Z37: SC (BLUMENAU) SSC3
E38: SGH6H62 | F38: =IFERROR(VLOOKUP(Tabela1[[#This Row],[Placa]],'Base Cadastro '!A:B,2,FALSE),"Correção de cadastro") -> TRANSIT FURGÃO | G38: 59751 | H38: Revisão(Pastilha de Freio) | I38: 45965 | J38: Hillary | K38: Manutenção | L38: Corretiva | M38: Negociando | P38: =VLOOKUP(Tabela1[[#This Row],[Placa]],'Base Cadastro '!A:M,13,FALSE) -> SSC3 | Q38: MERCADO LIVRE | R38: Em Manutenção | S38: 45980 | U38: =IFERROR(DATEDIF(Tabela1[[#This Row],[Data Agenda]],Tabela1[[#This Row],[Liberado]],"D"),DATEDIF(Tabela1[[#This Row],[Data Agenda]],TODAY(),"D")) -> 13 | V38: =IF(Tabela1[[#This Row],[D+Manut]]<=2,"Dentro do Prazo","Fora do Prazo") -> Fora do Prazo | W38: Ford AutoPlus | X38: Gabrieli | Y38: Nov | Z38: =VLOOKUP(Tabela1[[#This Row],[Placa]],DadosViagem5[[Placa]:[Base]],11,FALSE) -> SC (BLUMENAU) SSC3
C39: Sim | E39: RUX9G54 | F39: =IFERROR(VLOOKUP(Tabela1[[#This Row],[Placa]],'Base Cadastro '!A:B,2,FALSE),"Correção de cadastro") -> Fiorino Endurance Evo 1.4 2P | G39: N/E | H39: ASCENDEU LUZ DA INJEÇÃO EM SEGUIDA PERDEU FORÇA E PAROU DE FUNCIONAR | I39: 45968 | J39: Julia | K39: Manutenção | L39: Corretiva | M39: Negociando | P39: =VLOOKUP(Tabela1[[#This Row],[Placa]],'Base Cadastro '!A:M,13,FALSE) -> LMS36 | Q39: MERCADO LIVRE | R39: Em Manutenção | S39: 45980 | U39: =IFERROR(DATEDIF(Tabela1[[#This Row],[Data Agenda]],Tabela1[[#This Row],[Liberado]],"D"),DATEDIF(Tabela1[[#This Row],[Data Agenda]],TODAY(),"D")) -> 10 | V39: =IF(Tabela1[[#This Row],[D+Manut]]<=2,"Dentro do Prazo","Fora do Prazo") -> Fora do Prazo | W39: Wellington Gideoes Oficina | X39: TIAGO | Y39: Nov | Z39: SC (BAHIA SALVADOR) SBA1
E40: SGH6H64 | F40: =IFERROR(VLOOKUP(Tabela1[[#This Row],[Placa]],'Base Cadastro '!A:B,2,FALSE),"Correção de cadastro") -> TRANSIT FURGÃO | G40: N/E | H40: Pastilha de Freio | I40: 45971 | J40: Hillary | K40: Manutenção | L40: Corretiva | M40: Negociando | P40: =VLOOKUP(Tabela1[[#This Row],[Placa]],'Base Cadastro '!A:M,13,FALSE) -> SSC1 | Q40: MERCADO LIVRE | R40: Em Manutenção | S40: 45980 | U40: =IFERROR(DATEDIF(Tabela1[[#This Row],[Data Agenda]],Tabela1[[#This Row],[Liberado]],"D"),DATEDIF(Tabela1[[#This Row],[Data Agenda]],TODAY(),"D")) -> 7 | V40: =IF(Tabela1[[#This Row],[D+Manut]]<=2,"Dentro do Prazo","Fora do Prazo") -> Fora do Prazo | W40: Ford Globo | X40: Juliano | Y40: Nov. | Z40: =VLOOKUP(Tabela1[[#This Row],[Placa]],DadosViagem5[[Placa]:[Base]],11,FALSE) -> SC (JOINVILLE) SSC1
E41: RVB8A67 | F41: =IFERROR(VLOOKUP(Tabela1[[#This Row],[Placa]],'Base Cadastro '!A:B,2,FALSE),"Correção de cadastro") -> MASTER FURGAO L1 | G41: 92.338.0 | H41: Turbina | I41: 45971 | J41: Sara | K41: Manutenção | L41: Corretiva | M41: Negociando | P41: =VLOOKUP(Tabela1[[#This Row],[Placa]],'Base Cadastro '!A:M,13,FALSE) -> SPR2 | Q41: MERCADO LIVRE | R41: Em Manutenção | S41: 45981 | U41: =IFERROR(DATEDIF(Tabela1[[#This Row],[Data Agenda]],Tabela1[[#This Row],[Liberado]],"D"),DATEDIF(Tabela1[[#This Row],[Data Agenda]],TODAY(),"D")) -> 7 | V41: =IF(Tabela1[[#This Row],[D+Manut]]<=2,"Dentro do Prazo","Fora do Prazo") -> Fora do Prazo | W41: Cometa Car | X41: ANA | Y41: Nov. | Z41: =VLOOKUP(Tabela1[[#This Row],[Placa]],DadosViagem5[[Placa]:[Base]],11,FALSE) -> SC (LONDRINA) SPR2
...

Sheet Liberado
A1: Data Forms | B1: Atendimento | C1: Placa | D1: Modelo | E1: km | F1: Relato | G1: Data Agenda | H1: Focal | I1: Reparo | J1: Tipo de Manutenção | K1: Aprovação | L1: Valor do Orçamento | M1: Valor Negociado | N1: Centro de Custo | O1: Operação | P1: Status | Q1: Previsão de Entrega | R1: Liberado | S1: D+Manut | T1: Status2 | U1: Oficina | V1: Lider Base | W1: Mês | X1: Coluna1
C2: STU8B28 | D2: DELIVERY 9.180 | E2: 35410.421 | F2: 10/09/2025 Veiculo fazendo funilaria | G2: 45910 | H2: Miriam | I2: Manutenção | J2: Corretiva | K2: Aprovado | N2: =VLOOKUP(C2,'Base Cadastro '!A:M,13,FALSE) -> SSP5 | O2: MERCADO LIVRE | P2: Motor | Q2: 45924 | R2: 45919 | S2: 9 | T2: Fora do Prazo | U2: Central Truck | V2: MARCELO/ISLENE/ERIVELTON | W2: Set
A3: 0 | C3: RUM2B64 | D3: Fiorino Endurance Evo 1.4 2P | E3: 0 | F3: Motor/Junta do Cabeçote | G3: 45912 | H3: Hillary | I3: Manutenção | J3: Corretiva | K3: Aprovado | N3: =VLOOKUP(C3,'Base Cadastro '!A:M,13,FALSE) -> SSP20 | O3: MERCADO LIVRE | P3: Em Manutenção | Q3: 45924 | R3: 45922 | S3: 10 | T3: Fora do Prazo | U3: SM3 | V3: LARIANE | W3: Set
A4: 0 | C4: RVB8A68 | D4: MASTER FURGAO L1 | E4: 109052 | F4: 21/08 - Embreagem | G4: 45881 | H4: Miriam | I4: Manutenção | J4: Corretiva | K4: Aprovado | N4: =VLOOKUP(C4,'Base Cadastro '!A:M,13,FALSE) -> SPR2 | O4: MERCADO LIVRE | P4: Em Manutenção | Q4: 45924 | R4: 45919 | S4: 38 | T4: Fora do Prazo | U4: Auto Vans | V4: EDGARD | W4: Ago
C5: SDP9J20 | D5: E-Jumpy Furgão 2P | F5: Não é sinistro | G5: 45906 | H5: Hillary | I5: Sinistro | J5: Corretiva | K5: Aprovado | N5: =VLOOKUP(C5,'Base Cadastro '!A:M,13,FALSE) -> SSC2 | O5: MERCADO LIVRE | P5: Em Manutenção | Q5: 45924 | R5: 45919 | S5: 13 | T5: Fora do Prazo | U5: França pneus | V5: CARLOS SELL | W5: Set
B6: 6776496 | C6: RHV8D37 | D6: JAC iEV1200T AT 4x2 2P | E6: 38033 | F6: 28/08 Motor | G6: 45895 | H6: Miriam | I6: Manutenção | J6: Corretiva | K6: Aprovado | N6: =VLOOKUP(C6,'Base Cadastro '!A:M,13,FALSE) -> BRRC01 | O6: MERCADO LIVRE | P6: Em Manutenção | Q6: 45924 | R6: 45919 | S6: 24 | T6: Fora do Prazo | U6: NGN DISTRIBUIDORA DE VEICULOS LTDA (localiza) | V6: BRUNO/ERIVELTON | W6: Ago
C7: RUO6B02 | D7: Fiorino Endurance Evo 1.4 2P | F7: Vazamento de óleo/caixa de Direção | G7: 45908 | H7: Hillary | I7: Manutenção | J7: Corretiva | K7: Aprovado | N7: =VLOOKUP(C7,'Base Cadastro '!A:M,13,FALSE) -> PTL01 | O7: MERCADO LIVRE | P7: Em Manutenção | Q7: 45924 | R7: 45922 | S7: 14 | T7: Fora do Prazo | U7: RM | V7: CAMILA | W7: Set
C8: SDT9F97 | D8: E-Jumpy Furgão 2P | E8: 29453 | F8: Amortecedor | G8: 45905 | H8: Hillary | I8: Manutenção | J8: Corretiva | K8: Aprovado | N8: =VLOOKUP(C8,'Base Cadastro '!A:M,13,FALSE) -> SRS1 | O8: MERCADO LIVRE | P8: Em Manutenção | Q8: 45924 | R8: 45922 | S8: 17 | T8: Fora do Prazo | U8: Safety Car | V8: EVAILTON | W8: Set
C9: SGH9G33 | D9: I/FORD TRANSIT 350 FL | F9: pastilha de freio e correia alternador | G9: 45912 | H9: Hillary | I9: Manutenção | J9: Corretiva | K9: Aprovado | N9: =VLOOKUP(C9,'Base Cadastro '!A:M,13,FALSE) -> SSP20 | O9: MERCADO LIVRE | P9: Em Manutenção | Q9: 45924 | R9: 45919 | S9: 7 | T9: Fora do Prazo | U9: SM3 | V9: LARIANE | W9: Set
C10: RNJ9C97 | D10: Master Furgão 8m³ | E10: 1521700 | F10: 17/09 Problema eletrico em analise | G10: 45916 | H10: Miriam | I10: Manutenção | J10: Corretiva | K10: Aprovado | N10: =VLOOKUP(C10,'Base Cadastro '!A:M,13,FALSE) -> SPR8 | O10: MERCADO LIVRE | P10: Em Manutenção | Q10: 45924 | R10: 45919 | S10: 3 | T10: Fora do Prazo | U10: FSP | V10: TUANY | W10: Set
C11: RUM2B25 | D11: Fiorino Endurance Evo 1.4 2P | F11: veiculo guinchado por aquecimento | G11: 45914 | H11: Hillary | I11: Manutenção | J11: Corretiva | K11: Aprovado | N11: =VLOOKUP(C11,'Base Cadastro '!A:M,13,FALSE) -> SSP20 | O11: MERCADO LIVRE | P11: Em Manutenção | Q11: 45924 | R11: 45922 | S11: 8 | T11: Fora do Prazo | U11: SM3 | V11: LARIANE | W11: Set
A12: 45852 | B12: 6843992 | C12: EOA8G93 | D12: Partner Rapid Business Pack 1.4 2P | E12: 76689 | F12: Pane Eletrica | G12: 45841 | H12: Hillary | I12: Manutenção | J12: Corretiva | K12: Aprovado | N12: =VLOOKUP(C12,'Base Cadastro '!A:M,13,FALSE) -> SRS8 | O12: MERCADO LIVRE | P12: Em Manutenção | Q12: 45924 | R12: 45919 | S12: 78 | T12: Fora do Prazo | U12: Nova Lima (Movida) | V12: MICAEL MARCOS | W12: Jul
C13: RTM6B47 | D13: Master Furgão 8m³ | E13: 10000 | F13: vazamento oleo hidraulico e amortecedor lçado passageiro estourado | G13: 45913 | H13: Hillary | I13: Manutenção | J13: Corretiva | K13: Aprovado | N13: =VLOOKUP(C13,'Base Cadastro '!A:M,13,FALSE) -> SRS1 | O13: MERCADO LIVRE | P13: Em Manutenção | Q13: Em Diagnóstico | R13: 45919 | S13: 6 | T13: Fora do Prazo | U13: Safety Car | V13: EVAILTON | W13: Set
C14: RNJ9C89 | D14: Master Furgão 8m³ | F14: Arrebentou a Correia do Veículo | G14: 45918 | H14: Hillary | I14: Manutenção | J14: Corretiva | K14: Aprovado | N14: =VLOOKUP(C14,'Base Cadastro '!A:M,13,FALSE) -> SSC2 | O14: MERCADO LIVRE | P14: Em Manutenção | Q14: 45924 | R14: 45922 | S14: 4 | T14: Fora do Prazo | U14: AMS | V14: CARLOS SELL | W14: Set
C15: RNJ9D65 | D15: MASTER FURGAO L1 | E15: 15024732 | F15: CAIXA DE DIREÇÃO | G15: 45912 | H15: Carla | I15: Manutenção | J15: Corretiva | K15: Aprovado | N15: =VLOOKUP(C15,'Base Cadastro '!A:M,13,FALSE) -> SSP3 | O15: MERCADO LIVRE | P15: Em Manutenção | Q15: 45924 | R15: 45919 | S15: 7 | T15: Fora do Prazo | U15: Passos | V15: KAREN | W15: Set
C16: SGL1J04 | D16: TRANSIT FURGÃO | E16: 29123 | F16: pane | G16: 45916 | H16: Miriam | I16: Manutenção | J16: Corretiva | K16: Aprovado | N16: =VLOOKUP(C16,'Base Cadastro '!A:M,13,FALSE) -> SSP5 | O16: MERCADO LIVRE | P16: Em Manutenção | Q16: 45924 | R16: 45919 | S16: 3 | T16: Fora do Prazo | U16: Estacionamento da Coca/MuriTruck | V16: MARCELO/ISLENE/ERIVELTON | W16: Set
C17: RVD4C77 | D17: Partner Rapid Business Pack 1.4 2P | G17: 45913 | H17: Miriam | I17: Manutenção | J17: Corretiva | K17: Aprovado | N17: =VLOOKUP(C17,'Base Cadastro '!A:M,13,FALSE) -> SSP13 | O17: MERCADO LIVRE | P17: Em Manutenção | Q17: 45924 | R17: 45918 | S17: 5 | T17: Fora do Prazo | U17: Injemec | V17: NAYARA/FLAVIA | W17: Set
C18: RUX2J08 | D18: Partner Rapid Business Pack 1.4 2P | F18: embreagem | G18: 45913 | H18: Hillary | I18: Manutenção | J18: Corretiva | K18: Aprovado | N18: =VLOOKUP(C18,'Base Cadastro '!A:M,13,FALSE) -> SMG5 | O18: MERCADO LIVRE | P18: Em Manutenção | Q18: 45924 | R18: 45919 | S18: 6 | T18: Fora do Prazo | U18: centro automotivo full pneus | V18: CAMILA | W18: Set
C19: RNG5A20 | D19: Master Furgão 8m³ | F19: embreagem | G19: 45913 | H19: Hillary | I19: Manutenção | J19: Corretiva | K19: Aprovado | N19: =VLOOKUP(C19,'Base Cadastro '!A:M,13,FALSE) -> SSP20 | O19: MERCADO LIVRE | P19: Em Manutenção | Q19: 45924 | R19: 45922 | S19: 9 | T19: Fora do Prazo | U19: SM3 | V19: LARIANE | W19: Set
A20: 45909 | B20: 6775281 | C20: SDT9G93 | D20: E-Jumpy Furgão 2P | E20: 64412.329 | F20: Veículo elétrico não carrega | G20: 45861 | H20: Carla | I20: Manutenção | J20: Corretiva | K20: Aprovado | N20: =VLOOKUP(C20,'Base Cadastro '!A:M,13,FALSE) -> SSP12 | O20: MERCADO LIVRE | P20: Em Manutenção | Q20: 45924 | R20: 45918 | S20: 57 | T20: Fora do Prazo | U20: LUMIERE (CITROEN) | V20: GABRIEL | W20: Jul
C21: JCI8F75 | D21: DELIVERY 9.180 | F21: radiador avariado | G21: 45912 | H21: Hillary | I21: Manutenção | J21: Corretiva | K21: Aprovado | N21: =VLOOKUP(C21,'Base Cadastro '!A:M,13,FALSE) -> SSP20 | O21: MERCADO LIVRE | P21: Em Manutenção | Q21: 45924 | R21: 45922 | S21: 10 | T21: Fora do Prazo | U21: SM3 SOROCABA | V21: LARIANE | W21: Set
C22: RUM3C04 | D22: Fiorino Endurance Evo 1.4 2P | F22: pane eletrica | G22: 45914 | H22: Miriam | I22: Manutenção | J22: Corretiva | K22: Aprovado | N22: =VLOOKUP(C22,'Base Cadastro '!A:M,13,FALSE) -> EMS4 | O22: MERCADO LIVRE | P22: Em Manutenção | Q22: 45924 | R22: 45919 | S22: 5 | T22: Fora do Prazo | U22: Master tech | V22: MARIANE | W22: Set
A23: 45786 | B23: 6594053 | C23: SDT9F66 | D23: E-Jumpy Furgão 2P | E23: 37605 | F23: Veículo elétrico não carrega | G23: 45786 | H23: Miriam | I23: Manutenção | J23: Corretiva | K23: Aprovado | N23: =VLOOKUP(C23,'Base Cadastro '!A:M,13,FALSE) -> SSP21 | O23: MERCADO LIVRE | P23: Em Manutenção | Q23: 45924 | R23: 45919 | S23: 133 | T23: Fora do Prazo | U23: AKTA em Santos (localiza) | V23: JONATHAN | W23: Mai
A24: 45869 | B24: 6756576 | C24: SDP9J05 | D24: E-Jumpy Furgão 2P | E24: 49494 | F24: Veículo elétrico não carrega | G24: 45869 | H24: Khetlyn | I24: Manutenção | J24: Corretiva | K24: Aprovado | N24: =VLOOKUP(C24,'Base Cadastro '!A:M,13,FALSE) -> SCE1 | O24: MERCADO LIVRE | P24: Em Manutenção | Q24: 45924 | R24: 45916 | S24: 47 | T24: Fora do Prazo | U24: PIGALLE VEICULOS PEC (Localiza) | V24: GLEUMA | W24: Jul
A25: 45877 | B25: 6670135 | C25: SDQ3A32 | D25: Kangoo Z.E. MAXI 5 Lugares 2P | E25: 59013.494 | F25: Preventiva, estralando a Homocêntrica | G25: 45870 | H25: Carla | I25: Manutenção | J25: Corretiva | K25: Aprovado | N25: =VLOOKUP(C25,'Base Cadastro '!A:M,13,FALSE) -> SSP4 | O25: MERCADO LIVRE | P25: Em Manutenção | Q25: 45924 | R25: 45919 | S25: 49 | T25: Fora do Prazo | U25: EURO RP VEICULOS ( Localiza ) | V25: DEBORAH | W25: Ago
A26: 45869 | B26: 17148246 | C26: RHO5B26 | D26: JAC iEV1200T AT 4x2 2P | E26: 35760.542 | F26: fazendo barulho na roda dianteira muito forte (Homocinetica) | G26: 45838 | H26: Carla | I26: Manutenção | J26: Corretiva | K26: Aprovado | N26: =VLOOKUP(C26,'Base Cadastro '!A:M,13,FALSE) -> SSP30 | O26: MERCADO LIVRE | P26: Em Manutenção | Q26: 45924 | R26: 45919 | S26: 81 | T26: Fora do Prazo | U26: TICKET LOG MANUTENCA ( LOCALIZA ) | V26: CLAUDIA | W26: Jun
